Workbook

Sheet SUMÁRIO
B3: Nome completo:
B4: Navegador(a):
B5: Nome do Produto:
B6: Início da Preparação: | D6: 45663
B7: Data do Lançamento: | D7: 45712
D8: Esta é a data da Abertura de Carrinho.
B11: Progresso do seu Lançamento
B12: =(COUNTIF('PRÉ-REQUISITOS'!B25:B68,TRUE)+COUNTIF('CLI e AI'!B47:B68,TRUE)+COUNTIF(Lançamento!B25:B68,TRUE)+COUNTIF('Pós-Lançamento'!B20:B68,TRUE))/165 -> 0
C13: =IFERROR(__xludf.DUMMYFUNCTION("SPARKLINE(B12,{""charttype"",""bar"";""color1"",""#38a036"";""max"",1})"),"")
A16: VISÃO GERAL
C18: Pré-requisitos - tudo o que você já preparou até aqui
B19: ✅ | C19: Definir Nicho, Avatar e Roma
B20: ✅ | C20: Definir Oferta e Método
B21: ✅ | C21: Ter criado Redes Sociais que comunique o produto
B22: ✅ | C22: Frequência de Conteúdo para crescimento e nutrição de audiência
B23: ✅ | C23: Ter planejado os criativos
B24: ✅ | C24: Ter criado as páginas de captação e obrigado
B25: ✅ | C25: Ter criado a campanha de captação
B28: =CONCATENATE("ETAPA DE PREPARAÇÃO de ", TEXT(SUMÁRIO!$D$6,"DD/MM"), " a ", TEXT(SUMÁRIO!$D$6+(((SUMÁRIO!$D$7-21)-SUMÁRIO!$D$6)*1)-1,"DD/MM")) -> ETAPA DE PREPARAÇÃO de 06/01 a 02/02
B29: Durante esta etapa, você irá preparar tudo o que precisa para começar a sua captação.
B30: Revisar as etapas de Pré-requisitos
B31: Planejamento de Conteúdo de Aquecimento
B32: Criar as notificações de pré-lançamento
B35: =CONCATENATE("ETAPA DE CONSTRUÇÃO DE LISTA DE INSCRITOS (CLI) e AQUECIMENTO DE INSCRITOS (AI) - DE ", TEXT($D$7-21,"DD/MM"), " ATÉ ", TEXT($D$7-7,"DD/MM")) -> ETAPA DE CONSTRUÇÃO DE LISTA DE INSCRITOS (CLI) e AQUECIMENTO DE INSCRITOS (AI) - DE 03/02 ATÉ 17/02
B36: A sua captação de leads iniciou! Agora, é necessário aquecer a sua lista de inscritos, antecipando o lançamento!
B37: Captação de Leads
B38: Publicação dos Conteúdos de Aquecimento
B39: Otimização da campanha de captação
B40: Notificações de Lançamento
B41: Escrever o Script dos CPLs
B42: Criar as notificações de Lançamento
B45: =CONCATENATE("ETAPA DE PRÉ-LANÇAMENTO ", TEXT($D$7-7,"DD/MM"), " ATÉ ", TEXT($D$7-1,"DD/MM"), " (7 dias)") -> ETAPA DE PRÉ-LANÇAMENTO 17/02 ATÉ 23/02 (7 dias)
B46: Abertura dos CPL's
B47: Remarketing de CPL
B48: Criação da Campanha de Remarketing de Carrinho
B49: Planejamento dos Conteúdos de Carrinho Aberto
B50: Notificações de Carrinho
B51: Planejamento da Recuperação de Vendas
B54: =CONCATENATE("ETAPA DE LANÇAMENTO - DE ", TEXT($D$7,"DD/MM"), " ATÉ ", TEXT($D$7+4,"DD/MM")) -> ETAPA DE LANÇAMENTO - DE 24/02 ATÉ 28/02
B55: Nesta etapa você vai transmitir o Webinário, abrir o carrinho e iniciar a recuperação de vendas.
...

Sheet PRÉ-REQUISITOS
A1: PRÉ-REQUISITOS (este ciclo foi executado durante o estudo dos Fundamentos da Jornada)
A2: Lançamento Clássico
B3: =(COUNTIF(B18:B127,TRUE)/50) -> 0
C4: =IFERROR(__xludf.DUMMYFUNCTION("SPARKLINE(B3,{""charttype"",""bar"";""color1"",""#38a036"";""max"",1})"),"")
B7: 📄 | C7: DOCUMENTOS NECESSÁRIOS NESTE CICLO
C8: Caso tenha dúvidas de como utilizar esses documentos, acesse os tutoriais | D8: -> | E8: https://hotmart.com/pt-BR/club/am-insider/products/6130002/content/PeAg8qMPOW
B10: Launch Drive para produção do lançamento | D10: -> | E10: 1 | F10: Pasta 1) Documentação de Lançamento -> 2) Nicho, Avatar e Roma
E11: 2 | F11: Pasta 1) Documentação de Lançamento -> 4) Oferta - Visão Geral
E12: 3 | F12: Pasta 3) Criativos -> Mapa de Criativos
E13: 4 | F13: Pasta 2) Páginas
E14: 5 | F14: Pasta 4) Notificações -> 1) AI - Aquecimento de Inscritos -> 1) E-mails
E15: 6 | F15: Pasta 1) Documentação de Lançamento -> 8) Planilha de Tráfego
B18: PRÉ-REQUISITOS
B19: Para ter um bom lançamento, é necessário ter uma base sólida e bem definida. Você acabou de passar por uma fase que te desenvolveu para chegar até aqui com tudo isso pronto. Agora é o momento de revisar o que foi feito e se certificar que nada passou batido
B21: BASES
B22: O Nicho, Avatar, Roma e Método são as bases que vão delinear toda a sua estratégia de lançamento. Garanta que não exista nenhuma lacuna na definição dessas bases.
B23: 💻 Caso seja necessário, assista aos materiais enviados sobre o tema | D23: -> | F23: https://hotmart.com/pt-BR/club/am-insider/products/6130002/content/oODgEj2x7P
B25: FALSE | C25: Revise seu Nicho, Avatar e Roma
C26: Use o documento 1 listado em Documentos Necessários disponível no início dessa seção.
B27: FALSE | C27: Revise sua Oferta e Método
C28: Use o documento 2 listado em Documentos Necessários disponível no início dessa seção.
B30: AUDIÊNCIA
B31: Para que você consiga construir uma audiência qualificada, que se interessa pelo seu produto, é preciso comunicar a oportunidade de maneira certa nas suas redes sociais. Certifique-se que os seus perfis nas redes sociais estejam organizados de maneira que comunique a oportunidade de Roma.
B32: 💻 Caso sinta necessidade, assista aos materiais enviados sobre o tema | E32: -> | F32: https://hotmart.com/pt-BR/club/am-insider/products/6130002/content/3eaQBP8keg
B34: INSTAGRAM
B35: FALSE | C35: 1. Confirme que a sua conta do Instagram esteja configurada como um Perfil Comercial
B36: FALSE | C36: 2. Certifique-se de que a Roma está na bio
B37: FALSE | C37: 3. Coloque 1 post fixado quebrando objeções do seu avatar
B38: FALSE | C38: 4. Crie 1 destaque contando a história do expert. Exemplo: Comece por aqui - Jornada do Heroi (aqui você vai colocar a história do expert relacionando à história do método)
B39: FALSE | C39: 5. Crie 1 destaque explicando como os conteúdos do expert podem ajudar. Exemplo: Como eu posso te ajudar (mostre o valor do seu conteúdo) - Deve explicar a Roma - Deve explicar para quem se destina os conteúdos (avatar)
B40: FALSE | C40: 6. Crie 1 destaque com provas e depoimento dos alunos. Exemplo: Resultado dos alunos, caso tenha (depoimentos em vídeo, mensagens enviadas por direct, whatsapp etc...)
B42: FACEBOOK
B43: FALSE | C43: 1. Coloque uma capa que comunique a sua Roma exatamente como ela é
B45: YOUTUBE
B46: FALSE | C46: 1. Coloque uma capa que comunique a sua Roma
B47: FALSE | C47: 2. Grave um vídeo de boas-vindas e fixe na página inicial do seu canal
B49: CONTEÚDO
B50: Durante a Fase 02 você aprendeu a planejar conteúdos que comuniquem com o público certo. Além de publicar conteúdos, para intensificar o crescimento da audiência, você pode fazer a distribuição paga dos seus conteúdos.
B51: 🎯 | C51: Material complementar: ID de Construção de Audiência | D51: -> | F51: https://hotmart.com/pt-BR/club/am-insider/products/6130002/content/z7rBNrA27j
B53: FALSE | C53: Se planeje para postar pelo menos 5 reels/nutella e 1 raíz por semana
...

Sheet Preparação
A1: =CONCATENATE("Preparação de ", TEXT(SUMÁRIO!$D$6,"DD/MM"), " até ", TEXT(SUMÁRIO!$D$6+(((SUMÁRIO!$D$7-3)-SUMÁRIO!$D$6)*0.63)-1,"DD/MM")) -> Preparação de 06/01 até 02/02
A2: Lançamento Clássico
B3: =(COUNTIF(B65:B129,TRUE)/29) -> 0
C4: =IFERROR(__xludf.DUMMYFUNCTION("SPARKLINE(B3,{""charttype"",""bar"";""color1"",""#38a036"";""max"",1})"),"")
C8: O QUE ESPERAR NESTE CICLO
B9: Você já configurou todas as ferramentas necessárias para executar o seu lançamento, agora chegou a hora de implementar! Nessa fase, você deverá planejar seus conteúdos de aquecimento e escrever as copies das notificações de pré-lançamento que serão enviadas durante o período de Captação.
B10: Caso tenha dificuldade para concluir alguma atividade da fase de "Pré-requisitos", você pode ir ajustando as atividades paralelamente às atividades desta fase.
B11: ⚠️ Importante! Enquanto estiver neste ciclo, você deverá produzir e postar conteúdo, seguindo a frequência de pelo menos 4 reels e 1 raíz por semana.
B14: 💻 | C14: MATERIAIS DE APOIO DESTE CICLO (somente se precisar)
B15: CONTEÚDO
B16: 1 | C16: ID de Conteúdo Raíz | D16: -> | F16: https://hotmart.com/pt-BR/club/am-insider/products/6130002/content/NOwQyD3Mem
B17: 2 | C17: ID de Reels | D17: -> | F17: https://hotmart.com/pt-BR/club/am-insider/products/6130002/content/M7G9bwd94w
B18: DISTRIBUIÇÃO (opcional)
B19: 3 | C19: Curso de Tráfego 2.0 Módulo de Distribuição | D19: -> | F19: https://hotmart.com/pt-BR/club/am-insider/products/6130002/content/2OMJAXK146
B22: 📄 | C22: DOCUMENTOS NECESSÁRIOS NESTE CICLO
B23: Content Drive para produção e armazenamento de dados de distribuição | D23: -> | E23: 1 | F23: Pasta 1) Produção -> 1) Gerador de Raíz; 2) Gerador de Reels
E24: 2 | F24: Pasta 2) Distribuição -> 4) Métricas Reels e Distribuição de Conteúdo
E25: 3 | F25: Pasta 2) Distribuição -> 4) Crescimento de Audiência Google ADS
E26: 4 | F26: Pasta 1) Produção -> 4) Gerador de Conteúdo de Aquecimento
B28: Launch Drive para produção do lançamento | D28: -> | E28: 1 | F28: Pasta 4) Notificações
B31: PRODUÇÃO E PUBLICAÇÃO DE CONTEÚDO
B32: Enquanto você está preparando o seu lançamento, é necessário que mantenha a frequência de conteúdo. Caso tenha dúvida em como estruturar os conteúdos, utilize os materiais complementares e as instruções abaixo.
B34: 📢 Atenção! É ideal que você mantenha uma frequência de semanal, pelo menos:
B35: 5 reels / nutellas | E35: 1 raíz
B37: RAÍZ
B38: 📄 | C38: Utilize o documento 1, listado no início desta seção, para roteirizar o conteúdo raíz
B39: 🎯 | C39: Material complementar - Conteúdo Raíz
B40: FALSE | C40: Escolha as linhas editoriais e os temas de modo que consiga manter consistência e fazer 1 raíz por semana.
B41: FALSE | C41: Escreva as Estruturas de Roteiros dos temas listados, crie uma cópia para cada tema na aba "Estrutura de Roteiro" do arquivo 1) GERADOR DE RAIZ
B43: NUTELLA / REELS
B44: 📄 | C44: Utilize o documento 1, listado no início desta seção, para roteirizar seus reels
B45: 🎯 | C45: Material complementar - Reels
B46: FALSE | C46: Defina temas que conectam com seu avatar e que estejam alinhados à sua roma para gravar nos reels, seguindo a estrutura orientada no Launch Drive. É ideal que mantenha uma frequência de, pelo menos, 5 reels por semana
C47: 💡Você deve pensar na quantidade de reels a serem postados até começar a sua captação, tentando manter a frequência de pelo 5 reels por semana.
B50: Distribuição de Conteúdo
B51: Para o Lançamento Semente, distribuição de conteúdo não é determinante, mas pode ajudar a potencializar o crescimento da sua audiência, além de popular os públicos para a campanha de captação.
B52: 🎯 | C52: Material complementar - Distribuição de Conteúdo
B54: Turbinar - aumentando seu público para o Lançamento
B55: FALSE | C55: Confira seu orçamento para distribuição de acordo com a tabela.
B57: FACEBOOK | E57: GOOGLE
...

Sheet CLI e AI
A1: =CONCATENATE("Captação e Aquecimento de Leads - ",TEXT(SUMÁRIO!$D$7-21,"DD/MM")," até ",TEXT(SUMÁRIO!$D$7-8,"DD/MM"),) -> Captação e Aquecimento de Leads - 03/02 até 16/02
A2: Lançamento Clássico
B3: =(COUNTIF(B42:B394,TRUE)/87) -> 0
C4: =IFERROR(__xludf.DUMMYFUNCTION("SPARKLINE(B3,{""charttype"",""bar"";""color1"",""#38a036"";""max"",1})"),"")
C8: O QUE ESPERAR NESTE CICLO
B9: A sua captação de leads começou, o seu maior foco é acompanhar os dados de captação, fazer as otimizações da campanha e aquecer os inscritos.
B10: ⚠️ Você deverá fazer a otimização de orçamento diariamente, otimização de criativos 2x na semana e otimização de públicos 1x na semana.
B11: Além disso, você deverá postar os conteúdos de aquecimento (reels, stories, lives e áudios de WhatsApp) e enviar as notificações de pré-lançamento.
B14: 💻 | C14: MATERIAIS DE APOIO DESTE CICLO (somente se precisar)
B15: CAMPANHA DE CAPTAÇÃO DE LEADS - OTIMIZAÇÃO
B16: 1 | C16: Curso de Tráfego 2.0 - Aulas de Otimização - Facebook / Meta | E16: -> | F16: https://hotmart.com/pt-BR/club/am-insider/products/6130002/content/M7G9pg0V4w
B17: 2 | C17: Curso de Tráfego 2.0 - Aulas de Otimização - Google | F17: https://hotmart.com/pt-BR/club/am-insider/products/6130002/content/y4bVRL3P4R
B19: CAMPANHA DE REMARKETING
B20: 3 | C20: Cursto de Tráfego 2.0 - Criativos de Remarketing | E20: -> | F20: https://hotmart.com/pt-BR/club/am-insider/products/6130002/content/94J9p0MdOg
B21: 4 | C21: Curso de Tráfego 2.0 - Criação da Campanha de Remarketing de Antecipação | F21: https://hotmart.com/pt-BR/club/am-insider/products/6130002/content/gOpb2NqXeJ
B22: 5 | C22: Curso de Tráfego 2.0 - Planejamento de investimento de Remarketing de CPL | F22: https://hotmart.com/pt-BR/club/am-insider/products/6130002/content/k45QmVyN4l
B23: 6 | C23: Curso de Tráfego 2.0 - Criação da Campanha de Remarketing de CPL | F23: https://hotmart.com/pt-BR/club/am-insider/products/6130002/content/37d8aZXX7L
B25: SCRIPT DOS CPLS
B26: 7 | C26: ID de Script para Lançamento Clássico Parte I | E26: -> | F26: https://hotmart.com/pt-BR/club/am-insider/products/6130002/content/y4P9Dgrxex
B27: 8 | C27: ID de Script para Lançamento Clássico Parte II | F27: https://hotmart.com/pt-BR/club/am-insider/products/6130002/content/V7yx9WEqeJ
B30: 📄 | C30: DOCUMENTOS NECESSÁRIOS NESTE CICLO
B31: Launch Drive para produção do lançamento | D31: -> | E31: 1 | F31: Pasta 3) Criativos -> Mapa de Criativos -> Seção REMARKETING - ANTECIPAÇÃO
E32: 2 | F32: Pasta 1) Documentação de Lançamento -> 9) Planilha de Tráfego -> Aba PLANEJAMENTO DE LEADS e Aba PLANEJAMENTO DE CRIATIVOS
E33: 3 | F33: Pasta 6) CPLs e VV -> 1) Script CPL 1
E34: 4 | F34: Pasta 6) CPLs e VV -> 1) Script CPL 2
E35: 5 | F35: Pasta 6) CPLs e VV -> 3) Script CPL 3 e 4) Script VV
E36: 6 | F36: Pasta 1) Documentação de Lançamento -> 9) Planilha de Tráfego -> RMKT
E37: 7 | F37: Pasta 5) Notificações -> 3) Lançamentos -> 1) Email e 2) Whatsapp
B39: Content Drive para produção e e armazenamento de dados de distribuição | D39: -> | E39: 8 | F39: Pasta 1) Produção -> 4) Gerador de Conteúdo de Aquecimento -> Aba Vídeo de Antecipação
B43: =CONCATENATE(TEXT(SUMÁRIO!D7-21,"DD")," de ",TEXT(SUMÁRIO!D7-21,"MMMM")," - Início da Captação de Leads") -> 03 de fevereiro - Início da Captação de Leads
B44: =CONCATENATE("⚠️ Atenção! A sua Captação de Leads começa hoje, ",TEXT(SUMÁRIO!D7-21,"DD/MM")) -> ⚠️ Atenção! A sua Captação de Leads começa hoje, 03/02
B45: ⚠️ ATENÇÃO! Durante o período de Captação você deve Otimizar o Orçamento da sua campanha 1x ao dia todos os dias; Otimizar criativos duas vezes na semana; Otimizar os públicos 1x na semana.
B47: FALSE | C47: Verifique se suas campanhas de captação, programadas na semana passada, estão ativas conforme a data programada
B48: FALSE | C48: Coloque o Link da página captação na bio do Instagram, com um CTA atrativo
B49: FALSE | C49: Crie 1 post antecipando o seu lançamento e fixe no feed no início da captação. Esse post deve explicar sobre o que será o evento, quando e como se inscrever.
B50: FALSE | C50: Coloque 1 post fixado mostrando as provas do seu produto, com depoimentos de alunos, mensagens recebidas, print do direct etc.
B51: FALSE | C51: Envie a mensagem de boas vindas (preparada no ciclo anterior) no grupo do Whatsapp a cada 100 novos leads ou a cada 3 dias.
B54: =CONCATENATE(TEXT(SUMÁRIO!D7-21,"DD")," de ",TEXT(SUMÁRIO!D7-21,"MMMM")," - [OPCIONAL] Campanha de Remarketing de Aquecimento") -> 03 de fevereiro - [OPCIONAL] Campanha de Remarketing de Aquecimento
B55: A campanha de Remarketing de Aquecimento tem por objetivo aumentar o número de visualizações das lives de aquecimento. Isso é muito importante conscientizar a lead sobre oportunidade de Roma, fazendo seeding para o evento de pré-lançamento e a oferta. Programe a campanha para começar 3 dias após o início da captação de leads.
B56: 🎯 | C56: Material complementar - Remarketing de Aquecimento
...

Sheet Cópia de SEMANA 02 - CLI e AI I
A1: =CONCATENATE("CLI e AI I - ",TEXT(SUMÁRIO!D7-17,"DD/MM")," a ",TEXT(SUMÁRIO!D7-13,"DD/MM")) -> CLI e AI I - 07/02 a 11/02
A3: Semana 2 | Lançamento Semente
B4: =(COUNTIF(B9:B143,TRUE)+COUNTIF(E:E,TRUE))/52 -> 0
C5: =IFERROR(__xludf.DUMMYFUNCTION("SPARKLINE(B4,{""charttype"",""bar"";""color1"",""#38a036"";""max"",1})"),"")
B9: 📅 Agenda da Semana
B10: =CONCATENATE("📌 ",TEXT(SUMÁRIO!D7-21,"DD/MM")," - Call Semana 03") -> 📌 03/02 - Call Semana 03
B13: =CONCATENATE(TEXT(SUMÁRIO!D7-17,"DD")," de ",TEXT(SUMÁRIO!D7-23,"MMMM")," - Whatsapp e Pesquisa de Avatar") -> 07 de fevereiro - Whatsapp e Pesquisa de Avatar
B14: 1. Configurando Comunidade do WhatsApp
B15: 📓 Tutorial de como Criar Comunidade e Convidar Pessoas
B17: FALSE | C17: 1. Escolha um nome para a comunidade que identifique o seu evento e o número para a identificação da comunidade: Exemplo: Jornada 6em7 #1
B18: FALSE | C18: 2. Crie uma “capa” para inserir nas suas comunidades.
B19: FALSE | C19: 3. Certifique-se de adicionar administradores para as comunidades, por segurança no mínimo 3 administradores.
B20: FALSE | C20: 4. A quantidade de comunidades criadas vai depender da sua meta de captação de leads, cada comunidade cabe, em média, 2.000 pessoas.
B21: FALSE | C21: 5. Em cada chip de celular, crie no máximo 50 comunidades.
B22: FALSE | C22: 6. Adicione a descrição nas comunidades.
B24: 3. Mensagem de Boas-Vindas
B25: 📂 Acesse: LAUNCH DRIVE ➔ 5) NOTIFICAÇÕES ➔ 2) WHATSAPP OU TELEGRAM ➔ 1) BOAS VINDAS + PESQUISA
B27: FALSE | C27: 7. Crie uma mensagem de boas-vindas usando o Script BOAS-VINDAS + PESQUISA DE AVATAR disponível no seu Launch Drive (passe o mouse aqui pra ler um exemplo)
B28: FALSE | C28: 8. Depois de criar a mensagem na plataforma, basta selecionar a opção de “boas-vindas” que a mensagem será disparada automaticamente quando a comunidade lotar.
B30: 4. Convidar para a comunidade
B31: Convide sua lista de inscritos no lançamento para entrar no grupo (Distribuição de links)
B33: FALSE | C33: 9. Na página de obrigado do seu lançamento insira o link/botão que leve para a sua comunidade de WhatsApp.
B34: FALSE | C34: 10. No E-mail de confirmação de inscrição disponibilize o link para entrar na comunidade WhatsApp
B35: FALSE | C35: 11. Enviar mensagem de boas vindas à medida que o grupo lotar (caso não lote o grupo, pode mandar mensagem a cada X pessoas que entrarem ou a cada X dias)
B37: Pesquisa de Avatar
B38: 💡 Use o arquivo 6) PESQUISA DE AVATAR disponibilizado no seu Launch Drive e crie a sua pesquisa de avatar que será enviada posteriormente para sua lista
B39: 📂 Acesse: LAUNCH DRIVE ➔ 1) DOCUMENTAÇÃO DE LANÇAMENTO ➔ 6) PESQUISA DE AVATAR
B40: 👨‍🏫 Tutorial de como criar a sua Pesquisa de Avatar
B42: FALSE | C42: 1. Crie uma pesquisa de Avatar que será enviada posteriormente para suas leads no e-mail/mensagem de obrigado.
B44: =CONCATENATE(TEXT(SUMÁRIO!D7-16,"DD")," de ",TEXT(SUMÁRIO!D7-16,"MMMM")," - Configuração das Ferramentas") -> 08 de fevereiro - Configuração das Ferramentas
B45: 💻 Sugestão de conteúdo: ID de Ferramentas para LS
B46: 1. Páginas
B48: FALSE | C48: 1. Aponte o domínio para o HotmartPages - 👨‍🏫 Aula de Como Apontar Domínio
B49: FALSE | C49: 2. Criar página de Inscrição
B50: FALSE | C50: 3. Criar página de Obrigado
B51: FALSE | C51: 4. Criar página de Termos de Uso
B52: FALSE | C52: 5. Criar página de Política de Privacidade
B53: FALSE | C53: 6. Criar página de Replay
B55: 2. Transmissão
B57: FALSE | C57: 1. Configurar transmissão ao vivo no YouTube - 📓 Tutorial de como Configurar Transmissão
...

Sheet Pré-lançamento
A1: =CONCATENATE("Lançamento - ",TEXT(SUMÁRIO!$D$7-7,"DD/MM")," até ",TEXT(SUMÁRIO!$D$7-3,"DD/MM"),) -> Lançamento - 17/02 até 21/02
A2: Lançamento Clássico
B3: =(COUNTIF(B7:B206,TRUE)+COUNTIF(G:G,TRUE))/22 -> 0
C4: =IFERROR(__xludf.DUMMYFUNCTION("SPARKLINE(B3,{""charttype"",""bar"";""color1"",""#38a036"";""max"",1})"),"")
C8: O QUE ESPERAR NESTE CICLO
B9: Chegou a semana do seu lançamento! O seu maior foco agora é fazer com que o maior número possível de leads inscritas assistam aos CPLs. 🚀 Insira nos seus conteúdos, um CTA para que a sua audiência assista aos CPLs.
B10: Nesta fase, você deve garantir que todos os links do blog de lançamento estejam funcionando e que as notificações de pré-lançamento estão sendo enviadas.
B13: 💻 | C13: MATERIAIS DE APOIO DESTE CICLO (somente se precisar)
B14: Remarketing
B15: 1 | C15: Curso de Tráfego 2.0 - Remarketing de Carrinho | D15: -> | F15: https://hotmart.com/pt-BR/club/am-insider/products/6130002/content/Z72RmD8J7N
B18: 📄 | C18: DOCUMENTOS NECESSÁRIOS NESTE CICLO
B19: Launch Drive para Recuperação de Vendas | D19: -> | E19: 1 | F19: Pasta 5) Notificações -> 1) PL - Pré-lançamento -> 1) E-mails e 2) Whatsapp
E20: 2 | F20: Pasta 5) Notificações -> 4) Notificações E-mail - Cronograma e Relatórios
E21: 3 | F21: Pasta 7) Recuperação de Vendas -> 1) E-mails e 2) Whatsapp
B24: =CONCATENATE(TEXT(SUMÁRIO!D7-7,"DD")," de ",TEXT(SUMÁRIO!D7-7,"MMMM")," - Abertura CPL 1") -> 17 de fevereiro - Abertura CPL 1
B25: 💡 Libere os CPLs ao longo da semana, segunda, quarta e sexta, sempre no começo do dia para ter uma melhor taxa de comparecimento
B27: CPLs | E27: Data da liberação
B28: FALSE | C28: Liberar CPL 1 às 8h
B29: ⚠️ Confirme o agendamento dos emails de lançamento feita no ciclo de preparação. Teste todos os links e confirme a cada disparo se foi realizado.
B31: Conferir disparos e links (ideal que seja feito pela manhã)
B32: Disparos de Emails - Pré Lançamento | E32: Data
B33: FALSE | C33: Email CPL1 no ar | E33: =SUMÁRIO!$D$7-7 -> 45705
B34: FALSE | C34: Email CPL1 no ar - Reforço | E34: =E33+1 -> 45706
B35: Disparos de WhatsApp - Pré Lançamento | E35: Data
B36: FALSE | C36: CPL 1 no ar - Chamada 1 | E36: =SUMÁRIO!$D$7-7 -> 45705
B37: FALSE | C37: CPL 1 no ar - Chamada 2 | E37: =SUMÁRIO!$D$7-7 -> 45705
B38: FALSE | C38: Reforço CPL 1 - Chamada 1 | E38: =E36+1 -> 45706
B39: FALSE | C39: Reforço CPL 1 - Chamada 2 | E39: =E37+1 -> 45706
B42: =CONCATENATE(TEXT(SUMÁRIO!D7-7,"DD")," de ",TEXT(SUMÁRIO!D7-7,"MMMM")," - Remarketing de CPL") -> 17 de fevereiro - Remarketing de CPL
B43: 💡 | C43: Começa no dia da liberação do CPL 1
B44: FALSE | C44: Confirme o agendamento e configurações das suas campanhas de Remarketing que foram criadas no ciclo anterior
B47: =CONCATENATE(TEXT(SUMÁRIO!D7-7,"DD")," de ",TEXT(SUMÁRIO!D7-7,"MMMM")," - Criar e Agendar Notificações de Lançamento") -> 17 de fevereiro - Criar e Agendar Notificações de Lançamento
B48: 📄 | C48: Utilize o documento 1, listado em "Documentos Necessários" no início desta página
B50: E-mails
B51: 📄 | C51: Organize as datas dos disparos no documento 2, listado em "Documentos Necessários" no início desta seção.
B52: Tipo do E-mail | E52: Data
B53: FALSE | C53: Inscrições Abertas - Dia 1 #1 | E53: =SUMÁRIO!$D$7 -> 45712
B54: FALSE | C54: Cuidado! Você pode perder sua vaga. - Dia 1 #2 | E54: =SUMÁRIO!$D$7 -> 45712
B55: FALSE | C55: Últimas horas, as vagas estão esgotando.- Dia 1 #3 | E55: =SUMÁRIO!$D$7 -> 45712
B56: FALSE | C56: Estamos vivos... - Dia 2 #1 | E56: =E53+1 -> 45713
...

Sheet Lançamento
A1: =CONCATENATE("Lançamento - ",TEXT(SUMÁRIO!$D$7,"DD/MM")," até ",TEXT(SUMÁRIO!$D$7+4,"DD/MM"),) -> Lançamento - 24/02 até 28/02
A2: Lançamento Clássico
B3: =(COUNTIF(B7:B90,TRUE)+COUNTIF(G:G,TRUE))/22 -> 0
C4: =IFERROR(__xludf.DUMMYFUNCTION("SPARKLINE(B3,{""charttype"",""bar"";""color1"",""#38a036"";""max"",1})"),"")
C8: O QUE ESPERAR NESTE CICLO
B9: Chegou a semana do seu lançamento! O seu maior foco é realizar o maior número de vendas possível.
B10: Nesta fase, você deve garantir que as notificações de carrinho aberto estejam configuradas corretamente.
B11: Foco total na Recuperação de Vendas 🚀
B14: 💻 | C14: MATERIAIS DE APOIO DESTE CICLO
B15: Recuperação de Vendas
C16: Palestra de Recuperação de Vendas | D16: -> | F16: https://hotmart.com/pt-BR/club/am-insider/products/6130002/content/meL9A6Pj7n
B19: 📄 | C19: DOCUMENTOS NECESSÁRIOS NESTE CICLO
B20: Script de ligação para Recuperação de Vendas | D20: -> | E20: 1 | F20: https://hotmart.com/pt-BR/club/am-insider/products/6130002/content/k7Q1rYbx7y?track=Go4E0N1dOz
B21: Launch Drive | D21: -> | E21: 2 | F21: Pasta 6) Recuperação de Vendas -> 3) Planilha de Recuperação
B24: =CONCATENATE(TEXT(SUMÁRIO!D7-0,"DD")," de ",TEXT(SUMÁRIO!D7-0,"MMMM")," - Abertura do Carrinho") -> 24 de fevereiro - Abertura do Carrinho
B25: FALSE | C25: Liberar Vídeo de Vendas às 8h 🚀
B27: Conferir Disparos
B28: E-mail | E28: Whatsapp
B29: FALSE | C29: Inscrições Abertas - Dia 1, email 1 | E29: FALSE | F29: Inscrições Abertas - Dia 1, mensagem 1
B30: FALSE | C30: Cuidado! Você pode perder sua vaga - Dia 1, email 2 | E30: FALSE | F30: Cuidado! Você pode perder sua vaga. - Dia 1, mensagem 2
B31: FALSE | C31: Últimas horas, as vagas estão esgotando - Dia 1, email 3 | E31: FALSE | F31: Últimas horas, as vagas estão esgotando.- Dia 1, mensagem 3
B33: FALSE | C33: Confira se todos os links estão corretos
B36: =CONCATENATE(TEXT(SUMÁRIO!D7,"DD")," de ",TEXT(SUMÁRIO!D7,"MMMM")," - Remarketing de Carrinho") -> 24 de fevereiro - Remarketing de Carrinho
B37: 💡 | C37: Começa no dia da liberação do vídeo de vendas
B38: FALSE | C38: Confirme o agendamento e configurações das suas campanhas de Remarketing configuradas no ciclo anterior
B41: =CONCATENATE(TEXT(SUMÁRIO!D7,"DD")," de ",TEXT(SUMÁRIO!D7,"MMMM")," - Conteúdo de Lançamento") -> 24 de fevereiro - Conteúdo de Lançamento
B42: FALSE | C42: Publique o Reels com o tema que foi definido na Semana 04
B45: =CONCATENATE(TEXT(SUMÁRIO!D7+1,"DD")," de ",TEXT(SUMÁRIO!D7+1,"MMMM")," - Recuperação de Vendas") -> 25 de fevereiro - Recuperação de Vendas
B46: O expert deve entrar em contato com todas as leads que entraram na página de checkout até o carrinho fechar. Sugere-se que o contato seja realizado por telefone, mas se não conseguir fazer as ligações ou não se sentir confortável em ligar, entre em contato via WhatsApp. O mais importante é conseguir mapear e quebrar as objeções do avatar para fechar a maior quantidade de vendas possível.
B47: 📄 | C47: Acesse o documento 1, listado em "Documentos Necessários" no início desta seção
B48: 🎯 | C48: Material Complementar - Palestra Recuperação de Vendas
B49: =CONCATENATE("💡 Você deverá seguir com a recuperação de vendas até o fechamento do carrinho, dia ",TEXT(SUMÁRIO!D7+4,"DD/MM")) -> 💡 Você deverá seguir com a recuperação de vendas até o fechamento do carrinho, dia 28/02
B51: Whatsapp / Ligação
B52: FALSE | C52: Entre em contato com as leads também por mensagem 1a1 ou ligação seguindo o script do documento: - Apresentação - Conexão > fazer perguntas que façam sentido e tenham relação com o desejo do avatar e o produto, mostrando empatia. - Compromisso de Decisão > antecipar que a lead precisará tomar uma decisão ao final da conversa. - Oferta > descrição da oferta - Fechamento
B54: Confira os disparos configurados no ciclo anterior
B55: FALSE | C55: Mensagem de Boleto Emitido
B56: FALSE | C56: Mensagem de Compra Cancelada
B57: FALSE | C57: Preencha a Planilha de Recuperação, no seu Launch Drive, com os contatos e os Status das ações que executou
B58: 📄 | C58: Acesse o documento 2, listado em "Documentos Necessários" no início desta seção
B61: =CONCATENATE(TEXT(SUMÁRIO!D7+1,"DD")," de ",TEXT(SUMÁRIO!D7+1,"MMMM")," - Conteúdo de Lançamento") -> 25 de fevereiro - Conteúdo de Lançamento
...

Sheet Pós-Lançamento
A1: =CONCATENATE("Pós-Lançamento - ",TEXT(SUMÁRIO!$D$7+5,"DD/MM")," até ",TEXT(SUMÁRIO!$D$7+6,"DD/MM"),) -> Pós-Lançamento - 01/03 até 02/03
A2: Lançamento Clássico
B3: =(COUNTIF(B8:B39,TRUE)/6) -> 0
C4: =IFERROR(__xludf.DUMMYFUNCTION("SPARKLINE(B3,{""charttype"",""bar"";""color1"",""#38a036"";""max"",1})"),"")
C8: O QUE ESPERAR NESTE CICLO
B9: Parabéns, você executou o seu lançamento! Agora é hora de analisar os resultados. Neste momento, é importante preencher o debriefing na central de análises, disponível no Insider Desk, e solicitar uma análise com o Faixa Preta para receber um feedback assertivo e recomendações para o próximo lançamento.
B13: 📄 | C13: DOCUMENTOS NECESSÁRIOS NESTE CICLO
B14: Launch Drive para atualização da árvore de objeções | D14: -> | E14: 1 | F14: Pasta 1) Documentação de Lançamento 3) Árvore de Objeções
B17: =CONCATENATE(TEXT(SUMÁRIO!D7+5,"DD")," de ",TEXT(SUMÁRIO!D7+5,"MMMM")," - Fechamento de Carrinho") -> 01 de março - Fechamento de Carrinho
C18: Acesse o documento 1, listado no início desta seção.
B20: FALSE | C20: Feche o seu carrinho às 00:00
B21: FALSE | C21: Atualize sua árvore de objeções com as objeções novas que apareceram durante a recuperação de vendas.
B23: No Whatsapp
B24: FALSE | C24: Baixe o historico de conversa de todos os grupos - 📓 Tutorial de como baixar o histórico de conversa
B25: FALSE | C25: Exclua todos os participantes de cada grupo
B26: FALSE | C26: Exclua todos os grupos
B29: =CONCATENATE(TEXT(SUMÁRIO!D7+5,"DD")," de ",TEXT(SUMÁRIO!D7+5,"MMMM")," - Debriefing e Solicitação de Análise de Lançamento") -> 01 de março - Debriefing e Solicitação de Análise de Lançamento
B30: Esse passo é muito importante, pois é a partir do Feedback fornecido na análise de lançamento que você terá direcionamento para melhorar o próximo lançamento!
B32: FALSE | C32: Preencha o seu Debriefing no Insider Desk - 📓Tutorial para preenchimento do Debriefing
B33: FALSE | C33: Solicite a Análise do Lançamento na Comunidade, seguindo o padrão do post fixado no space 👉 https://fl-insider.circle.so/c/debriefing/
B34: FALSE | C34: Poste na comunidade o Criativo que teve o melhor resultado seguindo a orientação do post no space 👉 https://fl-insider.circle.so/c/criativos-criativos/
B35: FALSE | C35: Após análise de lançamento solicite a call de pós-análise com o seu navegador(a)
A38: PARABÉNS! VOCÊ CONCLUIU SEU LANÇAMENTO!
